INFO:botocore.credentials:Found credentials in shared credentials file: ~/.aws/credentials
INFO:root:24-05-2021-14-13-08
INFO:root:loaded class labels:
INFO:root:water
INFO:root:land
INFO:root:24-05-2021-14-13-08
INFO:root:Folder created: results/results2021-05-24-14-13
INFO:root:24-05-2021-14-13-08
INFO:root:Results will be written to results/results2021-05-24-14-13
INFO:werkzeug: * Running on http://127.0.0.1:8050/ (Press CTRL+C to quit)
INFO:werkzeug:127.0.0.1 - - [24/May/2021 14:13:15] "GET / HTTP/1.1" 200 -
INFO:werkzeug:127.0.0.1 - - [24/May/2021 14:13:15] "GET /_dash-dependencies HTTP/1.1" 200 -
INFO:werkzeug:127.0.0.1 - - [24/May/2021 14:13:15] "GET /_dash-layout HTTP/1.1" 200 -
INFO:werkzeug:127.0.0.1 - - [24/May/2021 14:13:15] "GET /_favicon.ico?v=1.12.0 HTTP/1.1" 200 -
INFO:root:24-05-2021-14-13-16
INFO:root:File list written to files_done.txt
ERROR:doodler_server:Exception on /_dash-update-component [POST]
Traceback (most recent call last):
  File "/home/marda/anaconda3/envs/dashdoodler/lib/python3.6/site-packages/flask/app.py", line 2447, in wsgi_app
    response = self.full_dispatch_request()
  File "/home/marda/anaconda3/envs/dashdoodler/lib/python3.6/site-packages/flask/app.py", line 1952, in full_dispatch_request
    rv = self.handle_user_exception(e)
  File "/home/marda/anaconda3/envs/dashdoodler/lib/python3.6/site-packages/flask/app.py", line 1821, in handle_user_exception
    reraise(exc_type, exc_value, tb)
  File "/home/marda/anaconda3/envs/dashdoodler/lib/python3.6/site-packages/flask/_compat.py", line 39, in reraise
    raise value
  File "/home/marda/anaconda3/envs/dashdoodler/lib/python3.6/site-packages/flask/app.py", line 1950, in full_dispatch_request
    rv = self.dispatch_request()
  File "/home/marda/anaconda3/envs/dashdoodler/lib/python3.6/site-packages/flask/app.py", line 1936, in dispatch_request
    return self.view_functions[rule.endpoint](**req.view_args)
  File "/home/marda/anaconda3/envs/dashdoodler/lib/python3.6/site-packages/dash/dash.py", line 1032, in dispatch
    response.set_data(func(*args, outputs_list=outputs_list))
  File "/home/marda/anaconda3/envs/dashdoodler/lib/python3.6/site-packages/dash/dash.py", line 967, in add_context
    output_value = func(*args, **kwargs)  # %% callback invoked %%
  File "doodler_server.py", line 821, in update_output
    if 'assets' not in select_image_value:
UnboundLocalError: local variable 'select_image_value' referenced before assignment
INFO:werkzeug:127.0.0.1 - - [24/May/2021 14:13:16] "[35m[1mPOST /_dash-update-component HTTP/1.1[0m" 500 -
INFO:root:24-05-2021-14-13-17
INFO:root:File list written to files_done.txt
ERROR:doodler_server:Exception on /_dash-update-component [POST]
Traceback (most recent call last):
  File "/home/marda/anaconda3/envs/dashdoodler/lib/python3.6/site-packages/flask/app.py", line 2447, in wsgi_app
    response = self.full_dispatch_request()
  File "/home/marda/anaconda3/envs/dashdoodler/lib/python3.6/site-packages/flask/app.py", line 1952, in full_dispatch_request
    rv = self.handle_user_exception(e)
  File "/home/marda/anaconda3/envs/dashdoodler/lib/python3.6/site-packages/flask/app.py", line 1821, in handle_user_exception
    reraise(exc_type, exc_value, tb)
  File "/home/marda/anaconda3/envs/dashdoodler/lib/python3.6/site-packages/flask/_compat.py", line 39, in reraise
    raise value
  File "/home/marda/anaconda3/envs/dashdoodler/lib/python3.6/site-packages/flask/app.py", line 1950, in full_dispatch_request
    rv = self.dispatch_request()
  File "/home/marda/anaconda3/envs/dashdoodler/lib/python3.6/site-packages/flask/app.py", line 1936, in dispatch_request
    return self.view_functions[rule.endpoint](**req.view_args)
  File "/home/marda/anaconda3/envs/dashdoodler/lib/python3.6/site-packages/dash/dash.py", line 1032, in dispatch
    response.set_data(func(*args, outputs_list=outputs_list))
  File "/home/marda/anaconda3/envs/dashdoodler/lib/python3.6/site-packages/dash/dash.py", line 967, in add_context
    output_value = func(*args, **kwargs)  # %% callback invoked %%
  File "doodler_server.py", line 821, in update_output
    if 'assets' not in select_image_value:
UnboundLocalError: local variable 'select_image_value' referenced before assignment
INFO:werkzeug:127.0.0.1 - - [24/May/2021 14:13:17] "[35m[1mPOST /_dash-update-component HTTP/1.1[0m" 500 -
